<?xml version="1.0" encoding="utf-8"?>
<!-- This URDF was automatically created by SolidWorks to URDF Exporter! Originally created by Stephen Brawner (brawner@gmail.com) 
     Commit Version: 1.6.0-4-g7f85cfe  Build Version: 1.6.7995.38578
     For more information, please see http://wiki.ros.org/sw_urdf_exporter -->
<robot
  name="Robot Kol Montaj">
  <link
    name="base_link">
    <inertial>
      <origin
        xyz="-4.7945E-05 0.003264 0.01968"
        rpy="0 0 0" />
      <mass
        value="0.7705" />
      <inertia
        ixx="0.0010798"
        ixy="-7.823E-08"
        ixz="-1.9556E-18"
        iyy="0.0010843"
        iyz="-1.7902E-18"
        izz="0.0015157" />
    </inertial>
    <visual>
      <origin
        xyz="0 0 0"
        rpy="0 0 0" />
      <geometry>
        <mesh
          filename="package://Robot Kol Montaj/meshes/base_link.STL" />
      </geometry>
      <material
        name="">
        <color
          rgba="0.89804 0.91765 0.92941 1" />
      </material>
    </visual>
    <collision>
      <origin
        xyz="0 0 0"
        rpy="0 0 0" />
      <geometry>
        <mesh
          filename="package://Robot Kol Montaj/meshes/base_link.STL" />
      </geometry>
    </collision>
  </link>
  <link
    name="Link_1">
    <inertial>
      <origin
        xyz="-4.1633E-17 -4.8572E-17 0.013474"
        rpy="0 0 0" />
      <mass
        value="0.77072" />
      <inertia
        ixx="0.0011517"
        ixy="2.4414E-07"
        ixz="3.5534E-18"
        iyy="0.0011377"
        iyz="3.0508E-18"
        izz="0.00031743" />
    </inertial>
    <visual>
      <origin
        xyz="0 0 0"
        rpy="0 0 0" />
      <geometry>
        <mesh
          filename="package://Robot Kol Montaj/meshes/Link_1.STL" />
      </geometry>
      <material
        name="">
        <color
          rgba="0.89804 0.91765 0.92941 1" />
      </material>
    </visual>
    <collision>
      <origin
        xyz="0 0 0"
        rpy="0 0 0" />
      <geometry>
        <mesh
          filename="package://Robot Kol Montaj/meshes/Link_1.STL" />
      </geometry>
    </collision>
  </link>
  <joint
    name="Joint_1"
    type="revolute">
    <origin
      xyz="0 0 0.0725"
      rpy="0 0 0" />
    <parent
      link="base_link" />
    <child
      link="Link_1" />
    <axis
      xyz="-0.017452 0.99985 0" />
    <limit
      lower="-3.142"
      upper="3.142"
      effort="1.041"
      velocity="7" />
  </joint>
  <link
    name="Link_2">
    <inertial>
      <origin
        xyz="0.040724 -2.1651E-10 -0.0045037"
        rpy="0 0 0" />
      <mass
        value="0.42915" />
      <inertia
        ixx="0.00024908"
        ixy="-4.2115E-12"
        ixz="-3.4302E-06"
        iyy="0.00059025"
        iyz="-1.2598E-12"
        izz="0.00044602" />
    </inertial>
    <visual>
      <origin
        xyz="0 0 0"
        rpy="0 0 0" />
      <geometry>
        <mesh
          filename="package://Robot Kol Montaj/meshes/Link_2.STL" />
      </geometry>
      <material
        name="">
        <color
          rgba="0.89804 0.91765 0.92941 1" />
      </material>
    </visual>
    <collision>
      <origin
        xyz="0 0 0"
        rpy="0 0 0" />
      <geometry>
        <mesh
          filename="package://Robot Kol Montaj/meshes/Link_2.STL" />
      </geometry>
    </collision>
  </link>
  <joint
    name="Joint_3"
    type="revolute">
    <origin
      xyz="0 0 0.0525"
      rpy="-1.5708 0 0" />
    <parent
      link="Link_1" />
    <child
      link="Link_2" />
    <axis
      xyz="0.017452 0 -0.99985" />
    <limit
      lower="0"
      upper="1.57"
      effort="2.31"
      velocity="7" />
  </joint>
  <link
    name="Link_3">
    <inertial>
      <origin
        xyz="0.033386 0.039528 0.00068996"
        rpy="0 0 0" />
      <mass
        value="0.76232" />
      <inertia
        ixx="0.0015582"
        ixy="-0.00019936"
        ixz="-3.4799E-06"
        iyy="0.00043677"
        iyz="-2.1318E-05"
        izz="0.0016577" />
    </inertial>
    <visual>
      <origin
        xyz="0 0 0"
        rpy="0 0 0" />
      <geometry>
        <mesh
          filename="package://Robot Kol Montaj/meshes/Link_3.STL" />
      </geometry>
      <material
        name="">
        <color
          rgba="0.89804 0.91765 0.92941 1" />
      </material>
    </visual>
    <collision>
      <origin
        xyz="0 0 0"
        rpy="0 0 0" />
      <geometry>
        <mesh
          filename="package://Robot Kol Montaj/meshes/Link_3.STL" />
      </geometry>
    </collision>
  </link>
  <joint
    name="Joint_4"
    type="revolute">
    <origin
      xyz="0.099985 0 0.0017452"
      rpy="0 0 -1.5708" />
    <parent
      link="Link_2" />
    <child
      link="Link_3" />
    <axis
      xyz="0 0.017452 -0.99985" />
    <limit
      lower="-1.57"
      upper="0"
      effort="2.0098"
      velocity="7" />
  </joint>
  <link
    name="Link_4">
    <inertial>
      <origin
        xyz="5.7562E-10 0.0060378 -3.7556E-10"
        rpy="0 0 0" />
      <mass
        value="0.18788" />
      <inertia
        ixx="9.5456E-05"
        ixy="-2.0317E-12"
        ixz="-1.3519E-07"
        iyy="3.7032E-05"
        iyz="1.157E-12"
        izz="0.0001032" />
    </inertial>
    <visual>
      <origin
        xyz="0 0 0"
        rpy="0 0 0" />
      <geometry>
        <mesh
          filename="package://Robot Kol Montaj/meshes/Link_4.STL" />
      </geometry>
      <material
        name="">
        <color
          rgba="0.89804 0.91765 0.92941 1" />
      </material>
    </visual>
    <collision>
      <origin
        xyz="0 0 0"
        rpy="0 0 0" />
      <geometry>
        <mesh
          filename="package://Robot Kol Montaj/meshes/Link_4.STL" />
      </geometry>
    </collision>
  </link>
  <joint
    name="Joint_5"
    type="revolute">
    <origin
      xyz="0.04 0.12298 0.0021466"
      rpy="0 0 1.5708" />
    <parent
      link="Link_3" />
    <child
      link="Link_4" />
    <axis
      xyz="0.017452 0 -0.99985" />
    <limit
      lower="0"
      upper="1.57"
      effort="0.6084"
      velocity="7" />
  </joint>
  <link
    name="Link_5">
    <inertial>
      <origin
        xyz="-0.0024996 4.4101E-05 0.0075"
        rpy="0 0 0" />
      <mass
        value="0.002025" />
      <inertia
        ixx="4.2187E-08"
        ixy="1.0245E-24"
        ixz="-1.731E-22"
        iyy="4.2187E-08"
        iyz="1.351E-22"
        izz="8.4375E-09" />
    </inertial>
    <visual>
      <origin
        xyz="0 0 0"
        rpy="0 0 0" />
      <geometry>
        <mesh
          filename="package://Robot Kol Montaj/meshes/Link_5.STL" />
      </geometry>
      <material
        name="">
        <color
          rgba="0.2 0.2 0.2 1" />
      </material>
    </visual>
    <collision>
      <origin
        xyz="0 0 0"
        rpy="0 0 0" />
      <geometry>
        <mesh
          filename="package://Robot Kol Montaj/meshes/Link_5.STL" />
      </geometry>
    </collision>
  </link>
  <joint
    name="Joint_7"
    type="prismatic">
    <origin
      xyz="0.0024996 0.07 4.3631E-05"
      rpy="-1.5708 0 0" />
    <parent
      link="Link_4" />
    <child
      link="Link_5" />
    <axis
      xyz="0.017452 0.99985 0" />
    <limit
      lower="0"
      upper="0.03"
      effort="0.3042"
      velocity="7" />
  </joint>
</robot>