<?xml version="1.0" encoding="utf-8"?>
<!-- This URDF was automatically created by SolidWorks to URDF Exporter! Originally created by Stephen Brawner (brawner@gmail.com) 
     Commit Version: 1.6.0-4-g7f85cfe  Build Version: 1.6.7995.38578
     For more information, please see http://wiki.ros.org/sw_urdf_exporter -->
<robot
  name="NuestroRobot2">
  <link
    name="base_link">
    <inertial>
      <origin
        xyz="-4.7945E-05 0.003264 0.01968"
        rpy="0 0 0" />
      <mass
        value="0.7705" />
      <inertia
        ixx="0.0010798"
        ixy="-7.823E-08"
        ixz="-1.9557E-18"
        iyy="0.0010843"
        iyz="-1.7901E-18"
        izz="0.0015157" />
    </inertial>
    <visual>
      <origin
        xyz="0 0 0"
        rpy="0 0 0" />
      <geometry>
        <mesh
          filename="package://NuestroRobot2/meshes/base_link.STL" />
      </geometry>
      <material
        name="">
        <color
          rgba="1 1 1 1" />
      </material>
    </visual>
    <collision>
      <origin
        xyz="0 0 0"
        rpy="0 0 0" />
      <geometry>
        <mesh
          filename="package://NuestroRobot2/meshes/base_link.STL" />
      </geometry>
    </collision>
  </link>
  <link
    name="Link_1">
    <inertial>
      <origin
        xyz="-3.0531E-16 -2.6021E-16 0.085974"
        rpy="0 0 0" />
      <mass
        value="0.77072" />
      <inertia
        ixx="0.0011517"
        ixy="2.4414E-07"
        ixz="3.5529E-18"
        iyy="0.0011377"
        iyz="3.0467E-18"
        izz="0.00031743" />
    </inertial>
    <visual>
      <origin
        xyz="0 0 0"
        rpy="0 0 0" />
      <geometry>
        <mesh
          filename="package://NuestroRobot2/meshes/Link_1.STL" />
      </geometry>
      <material
        name="">
        <color
          rgba="1 1 1 1" />
      </material>
    </visual>
    <collision>
      <origin
        xyz="0 0 0"
        rpy="0 0 0" />
      <geometry>
        <mesh
          filename="package://NuestroRobot2/meshes/Link_1.STL" />
      </geometry>
    </collision>
  </link>
  <joint
    name="Joint_1"
    type="revolute">
    <origin
      xyz="0 0 0"
      rpy="0 0 0" />
    <parent
      link="base_link" />
    <child
      link="Link_1" />
    <axis
      xyz="0 0 -1" />
    <limit
      lower="-3.142"
      upper="3.142"
      effort="1.041"
      velocity="7" />
    <dynamics
      damping="0"
      friction="0" />
  </joint>
  <link
    name="Link_2">
    <inertial>
      <origin
        xyz="0.040639 -2.1651E-10 -0.0052137"
        rpy="0 0 0" />
      <mass
        value="0.42915" />
      <inertia
        ixx="0.00024902"
        ixy="-4.2329E-12"
        ixz="8.4287E-09"
        iyy="0.00059025"
        iyz="-1.1861E-12"
        izz="0.00044608" />
    </inertial>
    <visual>
      <origin
        xyz="0 0 0"
        rpy="0 0 0" />
      <geometry>
        <mesh
          filename="package://NuestroRobot2/meshes/Link_2.STL" />
      </geometry>
      <material
        name="">
        <color
          rgba="1 1 1 1" />
      </material>
    </visual>
    <collision>
      <origin
        xyz="0 0 0"
        rpy="0 0 0" />
      <geometry>
        <mesh
          filename="package://NuestroRobot2/meshes/Link_2.STL" />
      </geometry>
    </collision>
  </link>
  <joint
    name="Joint_2"
    type="revolute">
    <origin
      xyz="0 0 0.125"
      rpy="-1.5708 0 0.017453" />
    <parent
      link="Link_1" />
    <child
      link="Link_2" />
    <axis
      xyz="0 0 -1" />
    <limit
      lower="0"
      upper="1.57"
      effort="2.31"
      velocity="7" />
    <dynamics
      damping="0"
      friction="0" />
  </joint>
  <link
    name="Link_3">
    <inertial>
      <origin
        xyz="0.033386 0.039534 -5.0307E-17"
        rpy="0 0 0" />
      <mass
        value="0.76232" />
      <inertia
        ixx="0.0015582"
        ixy="-0.00019939"
        ixz="3.9939E-20"
        iyy="0.0004364"
        iyz="-8.2971E-20"
        izz="0.0016581" />
    </inertial>
    <visual>
      <origin
        xyz="0 0 0"
        rpy="0 0 0" />
      <geometry>
        <mesh
          filename="package://NuestroRobot2/meshes/Link_3.STL" />
      </geometry>
      <material
        name="">
        <color
          rgba="1 1 1 1" />
      </material>
    </visual>
    <collision>
      <origin
        xyz="0 0 0"
        rpy="0 0 0" />
      <geometry>
        <mesh
          filename="package://NuestroRobot2/meshes/Link_3.STL" />
      </geometry>
    </collision>
  </link>
  <joint
    name="Joint_3"
    type="revolute">
    <origin
      xyz="0.1 0 0"
      rpy="0 0 -1.5708" />
    <parent
      link="Link_2" />
    <child
      link="Link_3" />
    <axis
      xyz="0 0 -1" />
    <limit
      lower="-1.57"
      upper="0"
      effort="2.0098"
      velocity="7" />
    <dynamics
      damping="0"
      friction="0" />
  </joint>
  <link
    name="Link_4">
    <inertial>
      <origin
        xyz="5.6898E-10 0.0060378 -3.8555E-10"
        rpy="0 0 0" />
      <mass
        value="0.18788" />
      <inertia
        ixx="9.5453E-05"
        ixy="-2.0112E-12"
        ixz="3.2459E-12"
        iyy="3.7032E-05"
        iyz="1.1923E-12"
        izz="0.0001032" />
    </inertial>
    <visual>
      <origin
        xyz="0 0 0"
        rpy="0 0 0" />
      <geometry>
        <mesh
          filename="package://NuestroRobot2/meshes/Link_4.STL" />
      </geometry>
      <material
        name="">
        <color
          rgba="1 1 1 1" />
      </material>
    </visual>
    <collision>
      <origin
        xyz="0 0 0"
        rpy="0 0 0" />
      <geometry>
        <mesh
          filename="package://NuestroRobot2/meshes/Link_4.STL" />
      </geometry>
    </collision>
  </link>
  <joint
    name="Joint_4"
    type="revolute">
    <origin
      xyz="0.04 0.123 0"
      rpy="0 0 1.5708" />
    <parent
      link="Link_3" />
    <child
      link="Link_4" />
    <axis
      xyz="0 0 -1" />
    <limit
      lower="0"
      upper="1.57"
      effort="0.6084"
      velocity="7" />
    <dynamics
      damping="0"
      friction="0" />
  </joint>
  <link
    name="Link_5">
    <inertial>
      <origin
        xyz="-0.0025 0.0075 -0.011208"
        rpy="0 0 0" />
      <mass
        value="0.0010125" />
      <inertia
        ixx="2.1094E-08"
        ixy="-8.6559E-23"
        ixz="-2.8434E-25"
        iyy="4.2187E-09"
        iyz="4.0839E-24"
        izz="2.1094E-08" />
    </inertial>
    <visual>
      <origin
        xyz="0 0 0"
        rpy="0 0 0" />
      <geometry>
        <mesh
          filename="package://NuestroRobot2/meshes/Link_5.STL" />
      </geometry>
      <material
        name="">
        <color
          rgba="1 1 1 1" />
      </material>
    </visual>
    <collision>
      <origin
        xyz="0 0 0"
        rpy="0 0 0" />
      <geometry>
        <mesh
          filename="package://NuestroRobot2/meshes/Link_5.STL" />
      </geometry>
    </collision>
  </link>
  <joint
    name="Joint_Left"
    type="prismatic">
    <origin
      xyz="0.0025 0.07 0"
      rpy="0 0 0" />
    <parent
      link="Link_4" />
    <child
      link="Link_5" />
    <axis
      xyz="0 0 -1" />
    <limit
      lower="-0.008"
      upper="0"
      effort="0.98066"
      velocity="7" />
    <dynamics
      damping="0"
      friction="0" />
  </joint>
  <link
    name="Link_6">
    <inertial>
      <origin
        xyz="-0.0025 0.0075 0.011207"
        rpy="0 0 0" />
      <mass
        value="0.0010125" />
      <inertia
        ixx="2.1094E-08"
        ixy="-8.673E-23"
        ixz="-1.0081E-24"
        iyy="4.2187E-09"
        iyz="2.2627E-24"
        izz="2.1094E-08" />
    </inertial>
    <visual>
      <origin
        xyz="0 0 0"
        rpy="0 0 0" />
      <geometry>
        <mesh
          filename="package://NuestroRobot2/meshes/Link_6.STL" />
      </geometry>
      <material
        name="">
        <color
          rgba="1 1 1 1" />
      </material>
    </visual>
    <collision>
      <origin
        xyz="0 0 0"
        rpy="0 0 0" />
      <geometry>
        <mesh
          filename="package://NuestroRobot2/meshes/Link_6.STL" />
      </geometry>
    </collision>
  </link>
  <joint
    name="Joint_Right"
    type="prismatic">
    <origin
      xyz="0.0025 0.07 0"
      rpy="0 0 0" />
    <parent
      link="Link_4" />
    <child
      link="Link_6" />
    <axis
      xyz="0 0 -1" />
    <limit
      lower="0"
      upper="0.008"
      effort="0.98066"
      velocity="7" />
    <dynamics
      damping="0"
      friction="0" />
  </joint>
</robot>